File: barrier_april_2025/04_21/04_21_viscostd_barrier.csv
Project:	anna_barrier_ceramic_04_21_2025

Test:	std d=1.5mm sweep

Result:	stress sweep auto 1

Interval and data points:	1	20
Interval data:	Point No.	Time	Shear Stress	Shear Rate	Viscosity	Gap	Complex Viscosity	Torque	Shear Strain	Time of Day	Normal Force

		[s]	[Pa]	[1/s]	[mPa·s]	[mm]	[mPa·s]	[mN·m]	[%]	[]	[N]
	1	5	0.0049981	-0.030236	-165.3	1.5		0.00018365	-5.75	4:43:18 PM	-0.00791
	2	10.001	0.0066077	-0.0399	-165.61	1.5		0.0002428	-25.4	4:43:23 PM	-0.00834
	3	15.002	0.0087329	-0.024331	-358.92	1.5		0.00032089	-42	4:43:28 PM	-0.008
	4	20.003	0.011542	0.0032269	3576.7	1.5		0.00042409	-47.6	4:43:33 PM	-0.00803
	5	25.004	0.015254	0.037089	411.27	1.5		0.00056048	-37.8	4:43:38 PM	-0.00771
	6	30.005	0.020159	0.082627	243.98	1.5		0.00074075	-8.36	4:43:43 PM	-0.00762
	7	35.006	0.026643	0.14134	188.5	1.5		0.00097899	47.1	4:43:48 PM	-0.00776
	8	40.007	0.035212	0.21459	164.09	1.5		0.0012938	136	4:43:53 PM	-0.00734
	9	45.008	0.046537	0.30668	151.74	1.5		0.00171	265	4:43:58 PM	-0.00758
	10	50.009	0.061504	0.43199	142.37	1.5		0.0022599	448	4:44:03 PM	-0.00748
	11	55.01	0.081285	0.63808	127.39	1.5		0.0029868	711	4:44:08 PM	-0.00713
	12	60.011	0.10743	0.97891	109.74	1.5		0.0039474	1.11E+03	4:44:13 PM	-0.00685
	13	65.012	0.14198	1.361	104.32	1.5		0.005217	1.7E+03	4:44:18 PM	-0.00683
	14	70.013	0.18764	1.8485	101.51	1.5		0.0068948	2.49E+03	4:44:23 PM	-0.00648
	15	75.014	0.24799	2.4481	101.3	1.5		0.0091124	3.56E+03	4:44:28 PM	-0.00715
	16	80.015	0.32775	3.2075	102.18	1.5		0.012043	4.97E+03	4:44:33 PM	-0.00795
	17	85.016	0.43316	4.1353	104.75	1.5		0.015916	6.8E+03	4:44:38 PM	-0.00816
	18	90.017	0.57248	5.4953	104.18	1.5		0.021035	9.18E+03	4:44:43 PM	-0.00765
	19	95.018	0.7566	7.3248	103.29	1.5		0.027801	1.24E+04	4:44:48 PM	-0.00775
	20	100.02	0.99994	9.641	103.72	1.5		0.036742	1.66E+04	4:44:53 PM	-0.00733

Interval and data points:	2	20
Interval data:	Point No.	Time	Shear Stress	Shear Rate	Viscosity	Gap	Complex Viscosity	Torque	Shear Strain	Time of Day	Normal Force

		[s]	[Pa]	[1/s]	[mPa·s]	[mm]	[mPa·s]	[mN·m]	[%]	[]	[N]
	1	105.02	1	10.931	91.486	1.5		0.036744	2.18E+04	4:44:58 PM	-0.00731
	2	110.02	0.75671	9.8101	77.136	1.5		0.027805	2.71E+04	4:45:03 PM	-0.00723
	3	115.02	0.57256	7.7394	73.979	1.5		0.021038	3.15E+04	4:45:08 PM	-0.00705
	4	120.02	0.43322	5.8755	73.735	1.5		0.015919	3.49E+04	4:45:13 PM	-0.0078
	5	125.03	0.3278	4.4802	73.166	1.5		0.012045	3.75E+04	4:45:18 PM	-0.00757
	6	130.03	0.24803	3.4368	72.168	1.5		0.0091137	3.94E+04	4:45:23 PM	-0.0074
	7	135.03	0.18767	2.5546	73.463	1.5		0.0068958	4.09E+04	4:45:28 PM	-0.00805
	8	140.03	0.142	1.8371	77.295	1.5		0.0052177	4.2E+04	4:45:33 PM	-0.0076
	9	145.03	0.10744	1.3725	78.282	1.5		0.003948	4.28E+04	4:45:38 PM	-0.00703
	10	150.03	0.081297	1.0944	74.287	1.5		0.0029872	4.34E+04	4:45:43 PM	-0.0073
	11	155.03	0.061513	0.86092	71.45	1.5		0.0022603	4.39E+04	4:45:48 PM	-0.00714
	12	160.03	0.046544	0.70663	65.867	1.5		0.0017102	4.43E+04	4:45:53 PM	-0.00731
	13	165.03	0.035217	0.52806	66.691	1.5		0.001294	4.46E+04	4:45:58 PM	-0.00749
	14	170.03	0.026647	0.39339	67.736	1.5		0.00097912	4.48E+04	4:46:03 PM	-0.00779
	15	175.04	0.020162	0.3265	61.754	1.5		0.00074085	4.5E+04	4:46:08 PM	-0.00748
	16	180.04	0.015256	0.29333	52.008	1.5		0.00056056	4.52E+04	4:46:13 PM	-0.00765
	17	185.04	0.011543	0.26251	43.972	1.5		0.00042415	4.53E+04	4:46:18 PM	-0.00751
	18	190.04	0.0087341	0.22322	39.128	1.5		0.00032093	4.54E+04	4:46:23 PM	-0.00754
	19	195.04	0.0066086	0.1785	37.023	1.5		0.00024283	4.55E+04	4:46:28 PM	-0.00788
	20	200.04	0.0050004	0.13521	36.983	1.5		0.00018374	4.56E+04	4:46:33 PM	-0.00736

Test:	std d=1mm sweep

Result:	stress sweep auto 1

Interval and data points:	1	20
Interval data:	Point No.	Time	Shear Stress	Shear Rate	Viscosity	Gap	Complex Viscosity	Torque	Shear Strain	Time of Day	Normal Force

		[s]	[Pa]	[1/s]	[mPa·s]	[mm]	[mPa·s]	[mN·m]	[%]	[]	[N]
	1	5.001	0.0049996	0.082816	60.37	1		0.00018371	16.5	4:51:12 PM	-0.0118
	2	10.002	0.006371	0.12345	51.607	1		0.0002341	71.9	4:51:17 PM	-0.0117
	3	15.003	0.0081184	0.13161	61.684	1		0.00029831	136	4:51:22 PM	-0.0112
	4	20.004	0.010345	0.14197	72.866	1		0.00038013	204	4:51:27 PM	-0.0107
	5	25.005	0.013183	0.15871	83.06	1		0.00048439	279	4:51:32 PM	-0.0114
	6	30.006	0.016798	0.1827	91.943	1		0.00061724	364	4:51:37 PM	-0.0109
	7	35.007	0.021405	0.213	100.49	1		0.00078653	463	4:51:42 PM	-0.011
	8	40.008	0.027276	0.25976	105.01	1		0.0010023	580	4:51:47 PM	-0.0111
	9	45.009	0.034758	0.32664	106.41	1		0.0012772	726	4:51:52 PM	-0.0115
	10	50.009	0.044291	0.42512	104.18	1		0.0016274	913	4:51:57 PM	-0.0116
	11	55.011	0.056439	0.56116	100.58	1		0.0020738	1.16E+03	4:52:02 PM	-0.0115
	12	60.012	0.071919	0.71964	99.937	1		0.0026426	1.48E+03	4:52:07 PM	-0.0118
	13	65.012	0.091644	0.8725	105.04	1		0.0033674	1.88E+03	4:52:12 PM	-0.0119
	14	70.014	0.11678	1.0456	111.69	1		0.004291	2.35E+03	4:52:17 PM	-0.0116
	15	75.015	0.14881	1.3377	111.24	1		0.0054679	2.94E+03	4:52:22 PM	-0.0119
	16	80.016	0.18962	1.6769	113.08	1		0.0069676	3.7E+03	4:52:27 PM	-0.0121
	17	85.017	0.24163	2.0792	116.21	1		0.0088787	4.63E+03	4:52:32 PM	-0.0117
	18	90.017	0.30791	2.685	114.68	1		0.011314	5.82E+03	4:52:37 PM	-0.0111
	19	95.019	0.39236	3.5571	110.3	1		0.014417	7.37E+03	4:52:42 PM	-0.0106
	20	100.02	0.49997	4.6077	108.51	1		0.018371	9.4E+03	4:52:47 PM	-0.0109

Interval and data points:	2	20
Interval data:	Point No.	Time	Shear Stress	Shear Rate	Viscosity	Gap	Complex Viscosity	Torque	Shear Strain	Time of Day	Normal Force

		[s]	[Pa]	[1/s]	[mPa·s]	[mm]	[mPa·s]	[mN·m]	[%]	[]	[N]
	1	105.02	0.5	4.9643	100.72	1		0.018372	1.18E+04	4:52:52 PM	-0.0114
	2	110.02	0.39241	4.1998	93.434	1		0.014419	1.42E+04	4:52:57 PM	-0.0124
	3	115.02	0.30795	3.2312	95.304	1		0.011315	1.6E+04	4:53:02 PM	-0.0121
	4	120.03	0.24166	2.5929	93.202	1		0.0088798	1.75E+04	4:53:07 PM	-0.0116
	5	125.03	0.18965	2.0891	90.781	1		0.0069685	1.86E+04	4:53:12 PM	-0.0117
	6	130.03	0.14883	1.6629	89.498	1		0.0054686	1.96E+04	4:53:17 PM	-0.0118
	7	135.03	0.11679	1.3192	88.533	1		0.0042915	2.03E+04	4:53:22 PM	-0.012
	8	140.03	0.091655	1.0797	84.888	1		0.0033678	2.09E+04	4:53:27 PM	-0.0116
	9	145.03	0.071927	0.81969	87.75	1		0.0026429	2.14E+04	4:53:32 PM	-0.0117
	10	150.03	0.056446	0.63087	89.473	1		0.0020741	2.17E+04	4:53:37 PM	-0.012
	11	155.03	0.044296	0.52226	84.817	1		0.0016276	2.2E+04	4:53:42 PM	-0.0123
	12	160.03	0.034762	0.44329	78.419	1		0.0012773	2.23E+04	4:53:47 PM	-0.0126
	13	165.03	0.02728	0.36505	74.728	1		0.0010024	2.25E+04	4:53:52 PM	-0.0127
	14	170.04	0.021408	0.28899	74.079	1		0.00078663	2.26E+04	4:53:57 PM	-0.0125
	15	175.04	0.0168	0.22003	76.355	1		0.00061732	2.28E+04	4:54:02 PM	-0.0124
	16	180.04	0.013184	0.16423	80.276	1		0.00048444	2.29E+04	4:54:07 PM	-0.0122
	17	185.04	0.010346	0.11895	86.982	1		0.00038017	2.29E+04	4:54:12 PM	-0.0124
	18	190.04	0.0081194	0.086287	94.098	1		0.00029834	2.3E+04	4:54:17 PM	-0.0124
	19	195.04	0.0063718	0.062173	102.48	1		0.00023413	2.3E+04	4:54:22 PM	-0.0121
	20	200.04	0.0050003	0.044132	113.3	1		0.00018373	2.3E+04	4:54:27 PM	-0.012

Test:	std d=0.5mm sweep

Result:	stress sweep auto 1

Interval and data points:	1	20
Interval data:	Point No.	Time	Shear Stress	Shear Rate	Viscosity	Gap	Complex Viscosity	Torque	Shear Strain	Time of Day	Normal Force

		[s]	[Pa]	[1/s]	[mPa·s]	[mm]	[mPa·s]	[mN·m]	[%]	[]	[N]
	1	5.001	0.0050042	0.0019785	2529.3	0.5		0.00018388	0.261	5:02:32 PM	-0.0356
	2	10.002	0.006371	0.015317	415.95	0.5		0.0002341	4.36	5:02:37 PM	-0.0356
	3	15.003	0.0081184	0.033735	240.65	0.5		0.00029831	16.5	5:02:42 PM	-0.0356
	4	20.003	0.010345	0.053621	192.93	0.5		0.00038013	38.3	5:02:47 PM	-0.0353
	5	25.005	0.013183	0.079664	165.48	0.5		0.00048439	71.5	5:02:52 PM	-0.0357
	6	30.006	0.016798	0.11185	150.18	0.5		0.00061724	119	5:02:57 PM	-0.0355
	7	35.007	0.021405	0.15138	141.4	0.5		0.00078653	185	5:03:02 PM	-0.0354
	8	40.008	0.027276	0.20442	133.43	0.5		0.0010023	273	5:03:07 PM	-0.0353
	9	45.009	0.034758	0.27021	128.63	0.5		0.0012772	392	5:03:12 PM	-0.0353
	10	50.01	0.044291	0.35453	124.93	0.5		0.0016274	547	5:03:17 PM	-0.0354
	11	55.011	0.056439	0.4648	121.42	0.5		0.0020738	751	5:03:22 PM	-0.0353
	12	60.012	0.071919	0.61114	117.68	0.5		0.0026426	1.02E+03	5:03:27 PM	-0.0353
	13	65.013	0.091644	0.81151	112.93	0.5		0.0033674	1.37E+03	5:03:32 PM	-0.0351
	14	70.014	0.11678	1.0891	107.22	0.5		0.004291	1.85E+03	5:03:37 PM	-0.035
	15	75.015	0.14881	1.458	102.06	0.5		0.0054679	2.48E+03	5:03:42 PM	-0.0349
	16	80.016	0.18962	1.8908	100.29	0.5		0.0069676	3.32E+03	5:03:47 PM	-0.0347
	17	85.017	0.24163	2.4069	100.39	0.5		0.0088787	4.39E+03	5:03:52 PM	-0.0344
	18	90.018	0.30791	3.1988	96.257	0.5		0.011314	5.78E+03	5:03:57 PM	-0.0341
	19	95.019	0.39236	4.1843	93.77	0.5		0.014417	7.62E+03	5:04:02 PM	-0.0343
	20	100.02	0.49997	5.3967	92.644	0.5		0.018371	1E+04	5:04:07 PM	-0.0344

Interval and data points:	2	20
Interval data:	Point No.	Time	Shear Stress	Shear Rate	Viscosity	Gap	Complex Viscosity	Torque	Shear Strain	Time of Day	Normal Force

		[s]	[Pa]	[1/s]	[mPa·s]	[mm]	[mPa·s]	[mN·m]	[%]	[]	[N]
	1	105.02	0.5	5.6696	88.19	0.5		0.018372	1.28E+04	5:04:12 PM	-0.0348
	2	110.02	0.39241	4.6972	83.541	0.5		0.014419	1.54E+04	5:04:17 PM	-0.035
	3	115.02	0.30795	3.6942	83.36	0.5		0.011315	1.75E+04	5:04:22 PM	-0.035
	4	120.03	0.24166	2.8354	85.23	0.5		0.0088798	1.92E+04	5:04:27 PM	-0.0353
	5	125.03	0.18965	2.2263	85.183	0.5		0.0069685	2.04E+04	5:04:32 PM	-0.0356
	6	130.03	0.14883	1.6607	89.617	0.5		0.0054686	2.14E+04	5:04:37 PM	-0.0349
	7	135.03	0.11679	1.2193	95.789	0.5		0.0042915	2.21E+04	5:04:42 PM	-0.035
	8	140.03	0.091655	0.92136	99.478	0.5		0.0033678	2.26E+04	5:04:47 PM	-0.0351
	9	145.03	0.071927	0.7094	101.39	0.5		0.0026429	2.3E+04	5:04:52 PM	-0.0346
	10	150.03	0.056446	0.54538	103.5	0.5		0.0020741	2.34E+04	5:04:57 PM	-0.0348
	11	155.03	0.044296	0.4111	107.75	0.5		0.0016276	2.36E+04	5:05:02 PM	-0.0349
	12	160.03	0.034762	0.29994	115.9	0.5		0.0012773	2.38E+04	5:05:07 PM	-0.035
	13	165.03	0.02728	0.21188	128.75	0.5		0.0010024	2.39E+04	5:05:12 PM	-0.0351
	14	170.04	0.021408	0.14223	150.52	0.5		0.00078663	2.4E+04	5:05:17 PM	-0.0349
	15	175.04	0.0168	0.085451	196.61	0.5		0.00061732	2.4E+04	5:05:22 PM	-0.0349
	16	180.04	0.013184	0.04024	327.64	0.5		0.00048444	2.41E+04	5:05:27 PM	-0.0348
	17	185.04	0.010346	0.008702	1189	0.5		0.00038017	2.41E+04	5:05:32 PM	-0.0344
	18	190.04	0.0081194	-0.01667	-487.07	0.5		0.00029834	2.41E+04	5:05:37 PM	-0.0343
	19	195.04	0.0063718	-0.038696	-164.66	0.5		0.00023413	2.41E+04	5:05:42 PM	-0.0343
	20	200.04	0.0050003	-0.053921	-92.735	0.5		0.00018373	2.4E+04	5:05:47 PM	-0.0342

Test:	std d=0.18mm sweep

Result:	stress sweep auto 1

Interval and data points:	1	20
Interval data:	Point No.	Time	Shear Stress	Shear Rate	Viscosity	Gap	Complex Viscosity	Torque	Shear Strain	Time of Day	Normal Force

		[s]	[Pa]	[1/s]	[mPa·s]	[mm]	[mPa·s]	[mN·m]	[%]	[]	[N]
	1	5	0.0050152	-0.071183	-70.455	0.18		0.00018428	-15.9	5:08:13 PM	-0.0555
	2	10.001	0.006371	-0.061973	-102.8	0.18		0.0002341	-51.4	5:08:18 PM	-0.0552
	3	15.002	0.0081184	-0.036405	-223	0.18		0.00029831	-76.3	5:08:23 PM	-0.0551
	4	20.003	0.010345	0.00044017	23503	0.18		0.00038013	-85.5	5:08:28 PM	-0.0547
	5	25.004	0.013183	0.042313	311.55	0.18		0.00048439	-74.8	5:08:33 PM	-0.0548
	6	30.005	0.016798	0.099898	168.15	0.18		0.00061724	-39.7	5:08:38 PM	-0.0545
	7	35.006	0.021405	0.17313	123.64	0.18		0.00078653	28.3	5:08:43 PM	-0.0539
	8	40.007	0.027276	0.25772	105.84	0.18		0.0010023	136	5:08:48 PM	-0.0538
	9	45.008	0.034758	0.36739	94.606	0.18		0.0012772	292	5:08:53 PM	-0.0542
	10	50.009	0.044291	0.50716	87.332	0.18		0.0016274	510	5:08:58 PM	-0.053
	11	55.01	0.056439	0.68587	82.288	0.18		0.0020738	807	5:09:03 PM	-0.0538
	12	60.011	0.071919	0.90842	79.169	0.18		0.0026426	1.21E+03	5:09:08 PM	-0.0535
	13	65.012	0.091644	1.1896	77.035	0.18		0.0033674	1.73E+03	5:09:13 PM	-0.0532
	14	70.013	0.11678	1.5665	74.548	0.18		0.004291	2.42E+03	5:09:18 PM	-0.0532
	15	75.014	0.14881	2.0539	72.451	0.18		0.0054679	3.32E+03	5:09:23 PM	-0.0531
	16	80.015	0.18962	2.704	70.127	0.18		0.0069676	4.5E+03	5:09:28 PM	-0.0528
	17	85.016	0.24163	3.5866	67.372	0.18		0.0088787	6.07E+03	5:09:33 PM	-0.0524
	18	90.017	0.30791	4.7454	64.885	0.18		0.011314	8.15E+03	5:09:38 PM	-0.0528
	19	95.018	0.39236	6.104	64.279	0.18		0.014417	1.09E+04	5:09:43 PM	-0.0527
	20	100.02	0.49997	7.7763	64.295	0.18		0.018371	1.43E+04	5:09:48 PM	-0.0526

Interval and data points:	2	20
Interval data:	Point No.	Time	Shear Stress	Shear Rate	Viscosity	Gap	Complex Viscosity	Torque	Shear Strain	Time of Day	Normal Force

		[s]	[Pa]	[1/s]	[mPa·s]	[mm]	[mPa·s]	[mN·m]	[%]	[]	[N]
	1	105.02	0.5	8.0723	61.94	0.18		0.018372	1.83E+04	5:09:53 PM	-0.0528
	2	110.02	0.39241	6.4766	60.588	0.18		0.014419	2.2E+04	5:09:58 PM	-0.0529
	3	115.02	0.30795	5.0945	60.446	0.18		0.011315	2.49E+04	5:10:03 PM	-0.0533
	4	120.02	0.24166	4.0933	59.038	0.18		0.0088798	2.72E+04	5:10:08 PM	-0.0529
	5	125.03	0.18965	3.2528	58.303	0.18		0.0069685	2.9E+04	5:10:13 PM	-0.0528
	6	130.03	0.14883	2.5304	58.816	0.18		0.0054686	3.04E+04	5:10:18 PM	-0.0523
	7	135.03	0.11679	1.9615	59.543	0.18		0.0042915	3.16E+04	5:10:23 PM	-0.0522
	8	140.03	0.091655	1.5227	60.192	0.18		0.0033678	3.24E+04	5:10:28 PM	-0.0517
	9	145.03	0.071927	1.1876	60.566	0.18		0.0026429	3.31E+04	5:10:33 PM	-0.0519
	10	150.03	0.056446	0.94065	60.007	0.18		0.0020741	3.36E+04	5:10:38 PM	-0.0514
	11	155.03	0.044296	0.74855	59.176	0.18		0.0016276	3.41E+04	5:10:43 PM	-0.0513
	12	160.03	0.034762	0.60076	57.863	0.18		0.0012773	3.44E+04	5:10:48 PM	-0.0517
	13	165.03	0.02728	0.48762	55.945	0.18		0.0010024	3.47E+04	5:10:53 PM	-0.0516
	14	170.03	0.021408	0.40128	53.35	0.18		0.00078663	3.49E+04	5:10:58 PM	-0.051
	15	175.04	0.0168	0.33179	50.635	0.18		0.00061732	3.51E+04	5:11:03 PM	-0.0507
	16	180.04	0.013184	0.27629	47.718	0.18		0.00048444	3.52E+04	5:11:08 PM	-0.0507
	17	185.04	0.010346	0.23358	44.296	0.18		0.00038017	3.54E+04	5:11:13 PM	-0.0506
	18	190.04	0.0081194	0.19834	40.936	0.18		0.00029834	3.55E+04	5:11:18 PM	-0.0503
	19	195.04	0.0063718	0.17343	36.74	0.18		0.00023413	3.56E+04	5:11:23 PM	-0.0498
	20	200.04	0.0050003	0.15448	32.368	0.18		0.00018373	3.56E+04	5:11:28 PM	-0.0501

Test:	std d=0.12mm sweep

Result:	stress sweep auto 1

Interval and data points:	1	20
Interval data:	Point No.	Time	Shear Stress	Shear Rate	Viscosity	Gap	Complex Viscosity	Torque	Shear Strain	Time of Day	Normal Force

		[s]	[Pa]	[1/s]	[mPa·s]	[mm]	[mPa·s]	[mN·m]	[%]	[]	[N]
	1	5.001	0.004992	0.21391	23.336	0.12		0.00018343	49.8	5:13:44 PM	-0.0567
	2	10.002	0.006371	0.25298	25.183	0.12		0.0002341	170	5:13:49 PM	-0.0565
	3	15.003	0.0081184	0.28877	28.114	0.12		0.00029831	305	5:13:54 PM	-0.0558
	4	20.004	0.010345	0.32905	31.44	0.12		0.00038013	460	5:13:59 PM	-0.056
	5	25.005	0.013183	0.38395	34.334	0.12		0.00048439	637	5:14:04 PM	-0.0556
	6	30.006	0.016798	0.44842	37.461	0.12		0.00061724	846	5:14:09 PM	-0.0556
	7	35.007	0.021405	0.52861	40.494	0.12		0.00078653	1.09E+03	5:14:14 PM	-0.0559
	8	40.008	0.027276	0.6272	43.489	0.12		0.0010023	1.38E+03	5:14:19 PM	-0.0555
	9	45.009	0.034758	0.75644	45.949	0.12		0.0012772	1.72E+03	5:14:24 PM	-0.055
	10	50.01	0.044291	0.92602	47.829	0.12		0.0016274	2.14E+03	5:14:29 PM	-0.0551
	11	55.011	0.056439	1.1382	49.585	0.12		0.0020738	2.66E+03	5:14:34 PM	-0.0551
	12	60.012	0.071919	1.3987	51.419	0.12		0.0026426	3.29E+03	5:14:39 PM	-0.0549
	13	65.013	0.091644	1.7401	52.667	0.12		0.0033674	4.08E+03	5:14:44 PM	-0.0544
	14	70.013	0.11678	2.182	53.519	0.12		0.004291	5.06E+03	5:14:49 PM	-0.0546
	15	75.015	0.14881	2.757	53.976	0.12		0.0054679	6.29E+03	5:14:54 PM	-0.0545
	16	80.016	0.18962	3.5085	54.047	0.12		0.0069676	7.85E+03	5:14:59 PM	-0.0545
	17	85.017	0.24163	4.5083	53.598	0.12		0.0088787	9.85E+03	5:15:04 PM	-0.0546
	18	90.018	0.30791	5.7895	53.184	0.12		0.011314	1.24E+04	5:15:09 PM	-0.0546
	19	95.018	0.39236	7.3423	53.438	0.12		0.014417	1.57E+04	5:15:14 PM	-0.0549
	20	100.02	0.49997	9.1856	54.43	0.12		0.018371	1.98E+04	5:15:19 PM	-0.0554

Interval and data points:	2	20
Interval data:	Point No.	Time	Shear Stress	Shear Rate	Viscosity	Gap	Complex Viscosity	Torque	Shear Strain	Time of Day	Normal Force

		[s]	[Pa]	[1/s]	[mPa·s]	[mm]	[mPa·s]	[mN·m]	[%]	[]	[N]
	1	105.02	0.5	9.2995	53.766	0.12		0.018372	2.45E+04	5:15:24 PM	-0.0557
	2	110.02	0.39241	7.4678	52.546	0.12		0.014419	2.87E+04	5:15:29 PM	-0.0563
	3	115.02	0.30795	5.8003	53.092	0.12		0.011315	3.2E+04	5:15:34 PM	-0.0557
	4	120.03	0.24166	4.455	54.246	0.12		0.0088798	3.46E+04	5:15:39 PM	-0.0556
	5	125.03	0.18965	3.43	55.29	0.12		0.0069685	3.65E+04	5:15:44 PM	-0.0548
	6	130.03	0.14883	2.6727	55.684	0.12		0.0054686	3.81E+04	5:15:49 PM	-0.0546
	7	135.03	0.11679	2.1014	55.58	0.12		0.0042915	3.93E+04	5:15:54 PM	-0.0544
	8	140.03	0.091655	1.6592	55.24	0.12		0.0033678	4.02E+04	5:15:59 PM	-0.0542
	9	145.03	0.071927	1.3171	54.611	0.12		0.0026429	4.09E+04	5:16:04 PM	-0.0538
	10	150.03	0.056446	1.043	54.121	0.12		0.0020741	4.15E+04	5:16:09 PM	-0.0539
	11	155.03	0.044296	0.82681	53.575	0.12		0.0016276	4.2E+04	5:16:14 PM	-0.053
	12	160.03	0.034762	0.65909	52.742	0.12		0.0012773	4.24E+04	5:16:19 PM	-0.0531
	13	165.03	0.02728	0.52375	52.086	0.12		0.0010024	4.27E+04	5:16:24 PM	-0.0525
	14	170.04	0.021408	0.41223	51.932	0.12		0.00078663	4.29E+04	5:16:29 PM	-0.0526
	15	175.04	0.0168	0.32834	51.168	0.12		0.00061732	4.31E+04	5:16:34 PM	-0.0524
	16	180.04	0.013184	0.25785	51.131	0.12		0.00048444	4.32E+04	5:16:39 PM	-0.0521
	17	185.04	0.010346	0.20808	49.723	0.12		0.00038017	4.33E+04	5:16:44 PM	-0.0523
	18	190.04	0.0081194	0.16825	48.259	0.12		0.00029834	4.34E+04	5:16:49 PM	-0.0521
	19	195.04	0.0063718	0.13728	46.413	0.12		0.00023413	4.35E+04	5:16:54 PM	-0.0517
	20	200.04	0.0050003	0.10787	46.353	0.12		0.00018373	4.36E+04	5:16:59 PM	-0.0513

Test:	std d=0.07mm sweep

Result:	stress sweep auto 1

Interval and data points:	1	20
Interval data:	Point No.	Time	Shear Stress	Shear Rate	Viscosity	Gap	Complex Viscosity	Torque	Shear Strain	Time of Day	Normal Force

		[s]	[Pa]	[1/s]	[mPa·s]	[mm]	[mPa·s]	[mN·m]	[%]	[]	[N]
	1	5.001	0.0049974	0.17982	27.792	0.06996		0.00018363	43.4	5:18:41 PM	-0.0546
	2	10.002	0.006371	0.2142	29.743	0.06996		0.0002341	143	5:18:46 PM	-0.0547
	3	15.003	0.0081184	0.26133	31.066	0.06996		0.00029831	261	5:18:51 PM	-0.0546
	4	20.004	0.010345	0.32047	32.281	0.06996		0.00038013	407	5:18:56 PM	-0.0538
	5	25.005	0.013183	0.39567	33.317	0.06996		0.00048439	586	5:19:01 PM	-0.0535
	6	30.006	0.016798	0.48641	34.535	0.06996		0.00061724	807	5:19:06 PM	-0.054
	7	35.006	0.021405	0.60254	35.525	0.06996		0.00078653	1.08E+03	5:19:11 PM	-0.0531
	8	40.008	0.027276	0.74892	36.421	0.06996		0.0010023	1.42E+03	5:19:16 PM	-0.0527
	9	45.009	0.034758	0.93603	37.133	0.06996		0.0012772	1.84E+03	5:19:21 PM	-0.0525
	10	50.01	0.044291	1.1759	37.667	0.06996		0.0016274	2.36E+03	5:19:26 PM	-0.0525
	11	55.011	0.056439	1.4802	38.13	0.06996		0.0020738	3.03E+03	5:19:31 PM	-0.0526
	12	60.012	0.071919	1.8678	38.505	0.06996		0.0026426	3.86E+03	5:19:36 PM	-0.0523
	13	65.013	0.091644	2.3546	38.921	0.06996		0.0033674	4.92E+03	5:19:41 PM	-0.0521
	14	70.014	0.11678	2.9713	39.303	0.06996		0.004291	6.25E+03	5:19:46 PM	-0.052
	15	75.015	0.14881	3.7734	39.436	0.06996		0.0054679	7.93E+03	5:19:51 PM	-0.0518
	16	80.016	0.18962	4.8167	39.368	0.06996		0.0069676	1.01E+04	5:19:56 PM	-0.052
	17	85.017	0.24163	6.1553	39.257	0.06996		0.0088787	1.28E+04	5:20:01 PM	-0.0516
	18	90.018	0.30791	7.8911	39.02	0.06996		0.011314	1.63E+04	5:20:06 PM	-0.0512
	19	95.019	0.39236	10.094	38.871	0.06996		0.014417	2.08E+04	5:20:11 PM	-0.0508
	20	100.02	0.49997	12.615	39.632	0.06996		0.018371	2.65E+04	5:20:16 PM	-0.0509

Interval and data points:	2	20
Interval data:	Point No.	Time	Shear Stress	Shear Rate	Viscosity	Gap	Complex Viscosity	Torque	Shear Strain	Time of Day	Normal Force

		[s]	[Pa]	[1/s]	[mPa·s]	[mm]	[mPa·s]	[mN·m]	[%]	[]	[N]
	1	105.02	0.5	12.487	40.041	0.06996		0.018372	3.28E+04	5:20:21 PM	-0.0514
	2	110.02	0.39241	9.4593	41.484	0.06996		0.014419	3.83E+04	5:20:26 PM	-0.0524
	3	115.02	0.30795	7.9902	38.54	0.06996		0.011315	4.27E+04	5:20:31 PM	-0.0521
	4	120.03	0.24166	6.37	37.938	0.06996		0.0088798	4.63E+04	5:20:36 PM	-0.052
	5	125.03	0.18965	4.768	39.775	0.06996		0.0069685	4.91E+04	5:20:41 PM	-0.0515
	6	130.03	0.14883	3.9175	37.99	0.06996		0.0054686	5.12E+04	5:20:46 PM	-0.0511
	7	135.03	0.11679	3.1399	37.196	0.06996		0.0042915	5.3E+04	5:20:51 PM	-0.0507
	8	140.03	0.091655	2.4844	36.892	0.06996		0.0033678	5.44E+04	5:20:56 PM	-0.0508
	9	145.03	0.071927	1.9475	36.934	0.06996		0.0026429	5.55E+04	5:21:01 PM	-0.0498
	10	150.03	0.056446	1.529	36.917	0.06997		0.0020741	5.64E+04	5:21:06 PM	-0.0496
	11	155.03	0.044296	1.2059	36.732	0.06997		0.0016276	5.7E+04	5:21:11 PM	-0.0492
	12	160.03	0.034762	0.94069	36.954	0.06997		0.0012773	5.76E+04	5:21:16 PM	-0.049
	13	165.03	0.02728	0.74471	36.632	0.06997		0.0010024	5.8E+04	5:21:21 PM	-0.048
	14	170.04	0.021408	0.58557	36.559	0.06997		0.00078663	5.83E+04	5:21:26 PM	-0.0483
	15	175.04	0.0168	0.45639	36.811	0.06997		0.00061732	5.86E+04	5:21:31 PM	-0.0479
	16	180.04	0.013184	0.36083	36.538	0.06997		0.00048444	5.88E+04	5:21:36 PM	-0.0475
	17	185.04	0.010346	0.28573	36.211	0.06997		0.00038017	5.89E+04	5:21:41 PM	-0.0466
	18	190.04	0.0081194	0.23056	35.216	0.06997		0.00029834	5.91E+04	5:21:46 PM	-0.0464
	19	195.04	0.0063718	0.18536	34.376	0.06997		0.00023413	5.92E+04	5:21:51 PM	-0.0461
	20	200.04	0.0050003	0.15566	32.124	0.06997		0.00018373	5.93E+04	5:21:56 PM	-0.0459

Test:	std d=0.05mm sweep

Result:	stress sweep auto 1

Interval and data points:	1	20
Interval data:	Point No.	Time	Shear Stress	Shear Rate	Viscosity	Gap	Complex Viscosity	Torque	Shear Strain	Time of Day	Normal Force

		[s]	[Pa]	[1/s]	[mPa·s]	[mm]	[mPa·s]	[mN·m]	[%]	[]	[N]
	1	5	0.0049926	0.19657	25.399	0.04995		0.00018345	56.4	5:24:45 PM	-0.0653
	2	10.001	0.006371	0.00084648	7526.5	0.04995		0.0002341	98.6	5:24:50 PM	-0.0649
	3	15.002	0.0081184	0.00044253	18346	0.04995		0.00029831	98.9	5:24:55 PM	-0.0645
	4	20.003	0.010345	-0.00024175	-42793	0.04995		0.00038013	99	5:25:00 PM	-0.0641
	5	25.004	0.013183	0.00013933	94614	0.04996		0.00048439	98.9	5:25:05 PM	-0.0637
	6	30.005	0.016798	0.00056065	29962	0.04996		0.00061724	99.2	5:25:10 PM	-0.0632
	7	35.006	0.021405	0.00057073	37506	0.04996		0.00078653	99.4	5:25:15 PM	-0.0629
	8	40.007	0.027276	0.0007282	37457	0.04996		0.0010023	99.8	5:25:20 PM	-0.0622
	9	45.008	0.034758	0.0017614	19733	0.04996		0.0012772	100	5:25:25 PM	-0.0615
	10	50.009	0.044291	0.0027641	16023	0.04996		0.0016274	102	5:25:30 PM	-0.0609
	11	55.01	0.056439	0.0034449	16383	0.04996		0.0020738	103	5:25:35 PM	-0.0604
	12	60.011	0.071919	0.0061002	11790	0.04996		0.0026426	106	5:25:40 PM	-0.0598
	13	65.012	0.091644	0.40162	228.19	0.04996		0.0033674	183	5:25:45 PM	-0.0593
	14	70.013	0.11678	0.41258	283.05	0.04996		0.004291	419	5:25:50 PM	-0.0598
	15	75.014	0.14881	0.65268	228	0.04996		0.0054679	682	5:25:55 PM	-0.0589
	16	80.015	0.18962	0.0121	15671	0.04996		0.0069676	845	5:26:00 PM	-0.0576
	17	85.016	0.24163	0.0087987	27462	0.04996		0.0088787	850	5:26:05 PM	-0.0566
	18	90.017	0.30791	0.0093321	32995	0.04996		0.011314	855	5:26:10 PM	-0.0555
	19	95.018	0.39236	0.0099648	39375	0.04996		0.014417	860	5:26:15 PM	-0.0541
	20	100.02	0.49997	0.012271	40744	0.04996		0.018371	866	5:26:20 PM	-0.0525

Interval and data points:	2	20
Interval data:	Point No.	Time	Shear Stress	Shear Rate	Viscosity	Gap	Complex Viscosity	Torque	Shear Strain	Time of Day	Normal Force

		[s]	[Pa]	[1/s]	[mPa·s]	[mm]	[mPa·s]	[mN·m]	[%]	[]	[N]
	1	105.02	0.5	0.0011536	4.3343E+05	0.04996		0.018372	867	5:26:25 PM	-0.052
	2	110.02	0.39241	-0.0028479	-1.3779E+05	0.04996		0.014419	866	5:26:30 PM	-0.0526
	3	115.02	0.30795	-0.0015415	-1.9977E+05	0.04996		0.011315	865	5:26:35 PM	-0.0531
	4	120.02	0.24166	-0.0024724	-97746	0.04996		0.0088798	864	5:26:40 PM	-0.053
	5	125.03	0.18965	-0.0023978	-79092	0.04996		0.0069685	863	5:26:45 PM	-0.0533
	6	130.03	0.14883	-0.0023743	-62682	0.04996		0.0054686	862	5:26:50 PM	-0.0534
	7	135.03	0.11679	-0.0017998	-64895	0.04996		0.0042915	860	5:26:55 PM	-0.0535
	8	140.03	0.091655	-0.00095565	-95909	0.04996		0.0033678	860	5:27:00 PM	-0.0536
	9	145.03	0.071927	-0.0011188	-64290	0.04996		0.0026429	859	5:27:05 PM	-0.0538
	10	150.03	0.056446	-0.0020301	-27804	0.04996		0.0020741	859	5:27:10 PM	-0.0532
	11	155.03	0.044296	-0.00074819	-59205	0.04996		0.0016276	858	5:27:15 PM	-0.0535
	12	160.03	0.034762	-0.0011108	-31293	0.04996		0.0012773	858	5:27:20 PM	-0.0533
	13	165.03	0.02728	-0.0021707	-12568	0.04996		0.0010024	857	5:27:25 PM	-0.0533
	14	170.03	0.021408	-0.0014316	-14954	0.04996		0.00078663	856	5:27:30 PM	-0.0529
	15	175.04	0.0168	-0.00034759	-48334	0.04996		0.00061732	855	5:27:35 PM	-0.0526
	16	180.04	0.013184	0.00010393	1.2686E+05	0.04996		0.00048444	855	5:27:40 PM	-0.0527
	17	185.04	0.010346	-0.0014509	-7131.2	0.04996		0.00038017	855	5:27:45 PM	-0.0524
	18	190.04	0.0081194	0.00026337	30829	0.04996		0.00029834	855	5:27:50 PM	-0.0526
	19	195.04	0.0063718	0.0010934	5827.7	0.04996		0.00023413	855	5:27:55 PM	-0.0521
	20	200.04	0.0050003	0.00020193	24763	0.04996		0.00018373	856	5:28:00 PM	-0.0517

Test:	std d=0.05mm 0.5pa

Result:	steady stress 1

Interval and data points:	1	467
Interval data:	Point No.	Time	Shear Stress	Shear Rate	Viscosity	Gap	Complex Viscosity	Torque	Shear Strain	Time of Day	Normal Force

		[s]	[Pa]	[1/s]	[mPa·s]	[mm]	[mPa·s]	[mN·m]	[%]	[]	[N]
	1	0.25	0.5	5.8824	84.999	0.04997		0.018372	73.3	5:29:00 PM	-0.0486
	2	0.5	0.5	1.8178	275.06	0.04997		0.018372	164	5:29:00 PM	-0.0437
	3	0.75	0.5	0.80744	619.24	0.04997		0.018372	198	5:29:00 PM	-0.0414
	4	1	0.5	1.4345	348.55	0.04997		0.018372	225	5:29:01 PM	-0.0397
	5	1.25	0.5	1.0903	458.58	0.04997		0.018372	256	5:29:01 PM	-0.0389
	6	1.5	0.5	2.3609	211.78	0.04997		0.018372	300	5:29:01 PM	-0.0402
	7	1.75	0.5	1.0318	484.6	0.04997		0.018372	344	5:29:01 PM	-0.0421
	8	2	0.5	1.0949	456.66	0.04997		0.018372	365	5:29:02 PM	-0.0442
	9	2.25	0.5	2.0266	246.72	0.04997		0.018372	406	5:29:02 PM	-0.044
	10	2.5	0.5	1.24	403.24	0.04997		0.018372	449	5:29:02 PM	-0.0447
	11	2.75	0.5	1.2518	399.41	0.04997		0.018372	480	5:29:02 PM	-0.0445
	12	3	0.5	1.1542	433.21	0.04997		0.018372	511	5:29:03 PM	-0.0446
	13	3.25	0.5	1.6159	309.42	0.04997		0.018372	548	5:29:03 PM	-0.0451
	14	3.5	0.5	1.4469	345.57	0.04997		0.018372	584	5:29:03 PM	-0.045
	15	3.75	0.5	0.97784	511.33	0.04997		0.018372	617	5:29:03 PM	-0.0447
	16	4	0.5	1.0531	474.8	0.04997		0.018372	640	5:29:04 PM	-0.0452
	17	4.25	0.5	1.0697	467.41	0.04997		0.018372	667	5:29:04 PM	-0.0447
	18	4.5	0.5	1.3957	358.25	0.04997		0.018372	695	5:29:04 PM	-0.0443
	19	4.75	0.5	1.6308	306.6	0.04997		0.018372	735	5:29:04 PM	-0.0446
	20	5	0.5	1.2996	384.74	0.04997		0.018372	770	5:29:05 PM	-0.0452
	21	5.25	0.5	1.8984	263.37	0.04997		0.018372	810	5:29:05 PM	-0.0453
	22	5.5	0.5	1.7485	285.95	0.04997		0.018372	855	5:29:05 PM	-0.0452
	23	5.75	0.5	2.616	191.13	0.04997		0.018372	905	5:29:05 PM	-0.0461
	24	6	0.5	2.7826	179.69	0.04997		0.018372	977	5:29:06 PM	-0.0456
	25	6.25	0.5	3.2574	153.5	0.04997		0.018372	1.05E+03	5:29:06 PM	-0.0451
	26	6.5	0.5	3.0093	166.15	0.04997		0.018372	1.14E+03	5:29:06 PM	-0.0452
	27	6.75	0.5	2.5227	198.2	0.04997		0.018372	1.2E+03	5:29:06 PM	-0.0461
	28	7	0.5	3.5002	142.85	0.04997		0.018372	1.27E+03	5:29:07 PM	-0.0464
	29	7.25	0.5	3.9601	126.26	0.04997		0.018372	1.37E+03	5:29:07 PM	-0.0462
	30	7.5	0.5	5.391	92.748	0.04997		0.018372	1.48E+03	5:29:07 PM	-0.0471
	31	7.75	0.5	5.5732	89.716	0.04997		0.018372	1.62E+03	5:29:07 PM	-0.047
	32	8	0.5	3.1517	158.65	0.04997		0.018372	1.74E+03	5:29:08 PM	-0.0442
	33	8.25	0.5	3.2932	151.83	0.04997		0.018372	1.81E+03	5:29:08 PM	-0.0426
	34	8.5	0.5	5.6636	88.283	0.04997		0.018372	1.93E+03	5:29:08 PM	-0.0451
	35	8.75	0.5	6.0556	82.568	0.04997		0.018372	2.07E+03	5:29:08 PM	-0.0458
	36	9	0.5	5.2539	95.168	0.04997		0.018372	2.22E+03	5:29:09 PM	-0.0446
	37	9.25	0.5	5.703	87.673	0.04997		0.018372	2.35E+03	5:29:09 PM	-0.0462
	38	9.5	0.5	0.030403	16446	0.04997		0.018372	2.41E+03	5:29:09 PM	-0.0438
	39	9.75	0.5	0.0077919	64169	0.04997		0.018372	2.41E+03	5:29:09 PM	-0.0445
	40	10	0.5	0.0055614	89905	0.04997		0.018372	2.41E+03	5:29:10 PM	-0.0445
	41	10.25	0.5	-0.0002648	-1.8882E+06	0.04997		0.018372	2.41E+03	5:29:10 PM	-0.0447
	42	10.5	0.5	0.0044321	1.1281E+05	0.04997		0.018372	2.41E+03	5:29:10 PM	-0.0443
	43	10.75	0.5	0.0059613	83874	0.04997		0.018372	2.41E+03	5:29:10 PM	-0.0442
	44	11	0.5	0.0020237	2.4707E+05	0.04997		0.018372	2.41E+03	5:29:11 PM	-0.0446
	45	11.25	0.5	0.0026766	1.868E+05	0.04997		0.018372	2.41E+03	5:29:11 PM	-0.0442
	46	11.5	0.5	0.0054145	92344	0.04997		0.018372	2.41E+03	5:29:11 PM	-0.0439
	47	11.75	0.5	-0.0014348	-3.4847E+05	0.04997		0.018372	2.41E+03	5:29:11 PM	-0.0442
	48	12	0.5	0.0022041	2.2685E+05	0.04997		0.018372	2.41E+03	5:29:12 PM	-0.0428
	49	12.25	0.5	0.0027923	1.7906E+05	0.04997		0.018372	2.41E+03	5:29:12 PM	-0.0439
	50	12.5	0.5	-0.00026542	-1.8838E+06	0.04997		0.018372	2.41E+03	5:29:12 PM	-0.0441
	51	12.75	0.5	0.0004495	1.1123E+06	0.04997		0.018372	2.41E+03	5:29:12 PM	-0.0429
	52	13	0.5	0.0010505	4.7597E+05	0.04997		0.018372	2.41E+03	5:29:13 PM	-0.0435
	53	13.25	0.5	-0.002454	-2.0375E+05	0.04997		0.018372	2.41E+03	5:29:13 PM	-0.0445
	54	13.5	0.5	-0.0017592	-2.8421E+05	0.04997		0.018372	2.41E+03	5:29:13 PM	-0.0451
	55	13.75	0.5	0.0016217	3.0831E+05	0.04997		0.018372	2.41E+03	5:29:13 PM	-0.0447
	56	14	0.5	0.0025502	1.9606E+05	0.04997		0.018372	2.41E+03	5:29:14 PM	-0.0446
	57	14.25	0.5	0.00099619	5.0191E+05	0.04997		0.018372	2.41E+03	5:29:14 PM	-0.0449
	58	14.5	0.5	0.0048782	1.025E+05	0.04997		0.018372	2.41E+03	5:29:14 PM	-0.0446
	59	14.75	0.5	0.0032927	1.5185E+05	0.04997		0.018372	2.41E+03	5:29:14 PM	-0.0429
	60	15	0.5	0.0032819	1.5235E+05	0.04997		0.018372	2.41E+03	5:29:15 PM	-0.0446
	61	15.25	0.5	0.00073728	6.7817E+05	0.04997		0.018372	2.41E+03	5:29:15 PM	-0.0436
	62	15.5	0.5	-0.0023292	-2.1467E+05	0.04997		0.018372	2.41E+03	5:29:15 PM	-0.0438
	63	15.75	0.5	0.00061652	8.1101E+05	0.04997		0.018372	2.41E+03	5:29:15 PM	-0.0445
	64	16	0.5	0.00057803	8.6501E+05	0.04997		0.018372	2.41E+03	5:29:16 PM	-0.0439
	65	16.25	0.5	-0.0032754	-1.5265E+05	0.04997		0.018372	2.41E+03	5:29:16 PM	-0.0437
	66	16.5	0.5	-0.0018691	-2.6751E+05	0.04997		0.018372	2.41E+03	5:29:16 PM	-0.0435
	67	16.75	0.5	5.9915E-05	8.3452E+06	0.04997		0.018372	2.41E+03	5:29:16 PM	-0.0451
	68	17	0.5	-0.0037764	-1.324E+05	0.04997		0.018372	2.41E+03	5:29:17 PM	-0.0438
	69	17.25	0.5	0.0047282	1.0575E+05	0.04997		0.018372	2.41E+03	5:29:17 PM	-0.0442
	70	17.5	0.5	0.0022072	2.2653E+05	0.04997		0.018372	2.41E+03	5:29:17 PM	-0.0443
	71	17.75	0.5	-0.0039254	-1.2738E+05	0.04997		0.018372	2.41E+03	5:29:17 PM	-0.0445
	72	18	0.5	0.0024919	2.0065E+05	0.04997		0.018372	2.41E+03	5:29:18 PM	-0.045
	73	18.25	0.5	0.00136	3.6764E+05	0.04997		0.018372	2.41E+03	5:29:18 PM	-0.0435
	74	18.5	0.5	-0.0015615	-3.2021E+05	0.04997		0.018372	2.41E+03	5:29:18 PM	-0.044
	75	18.75	0.5	0.003822	1.3082E+05	0.04997		0.018372	2.41E+03	5:29:18 PM	-0.0432
	76	19	0.5	-0.00040139	-1.2457E+06	0.04997		0.018372	2.41E+03	5:29:19 PM	-0.0434
	77	19.25	0.5	-0.0033608	-1.4878E+05	0.04997		0.018372	2.41E+03	5:29:19 PM	-0.0439
	78	19.5	0.5	0.0012955	3.8597E+05	0.04997		0.018372	2.41E+03	5:29:19 PM	-0.0444
	79	19.75	0.5	0.00037376	1.3377E+06	0.04997		0.018372	2.41E+03	5:29:19 PM	-0.044
	80	20	0.5	-0.0061692	-81048	0.04997		0.018372	2.41E+03	5:29:20 PM	-0.0433
	81	20.25	0.5	0.0018663	2.6791E+05	0.04997		0.018372	2.41E+03	5:29:20 PM	-0.0441
	82	20.5	0.5	0.0017006	2.9402E+05	0.04997		0.018372	2.41E+03	5:29:20 PM	-0.0439
	83	20.75	0.5	-0.0024708	-2.0237E+05	0.04997		0.018372	2.41E+03	5:29:20 PM	-0.0446
	84	21	0.5	-0.0015711	-3.1825E+05	0.04997		0.018372	2.41E+03	5:29:21 PM	-0.0445
	85	21.25	0.5	0.0039952	1.2515E+05	0.04997		0.018372	2.41E+03	5:29:21 PM	-0.0428
	86	21.5	0.5	0.001604	3.1172E+05	0.04997		0.018372	2.41E+03	5:29:21 PM	-0.0435
	87	21.75	0.5	-0.00053115	-9.4135E+05	0.04997		0.018372	2.41E+03	5:29:21 PM	-0.0431
	88	22	0.5	0.002454	2.0375E+05	0.04997		0.018372	2.41E+03	5:29:22 PM	-0.0437
	89	22.25	0.5	0.00087633	5.7056E+05	0.04997		0.018372	2.41E+03	5:29:22 PM	-0.0429
	90	22.5	0.5	0.00022785	2.1944E+06	0.04997		0.018372	2.41E+03	5:29:22 PM	-0.0428
	91	22.75	0.5	0.0026176	1.9101E+05	0.04997		0.018372	2.41E+03	5:29:22 PM	-0.0429
	92	23	0.5	-0.0032328	-1.5466E+05	0.04997		0.018372	2.41E+03	5:29:23 PM	-0.043
	93	23.25	0.5	-0.0032555	-1.5358E+05	0.04997		0.018372	2.41E+03	5:29:23 PM	-0.0443
	94	23.5	0.5	0.000723	6.9156E+05	0.04997		0.018372	2.41E+03	5:29:23 PM	-0.0434
	95	23.75	0.5	0.001558	3.2091E+05	0.04997		0.018372	2.41E+03	5:29:23 PM	-0.0438
	96	24	0.5	0.0018775	2.6631E+05	0.04997		0.018372	2.41E+03	5:29:24 PM	-0.0436
	97	24.25	0.5	0.0025744	1.9422E+05	0.04997		0.018372	2.41E+03	5:29:24 PM	-0.0441
	98	24.5	0.5	-0.00040728	-1.2276E+06	0.04997		0.018372	2.41E+03	5:29:24 PM	-0.044
	99	24.75	0.5	0.004216	1.186E+05	0.04997		0.018372	2.41E+03	5:29:24 PM	-0.0434
	100	25	0.5	0.00089435	5.5907E+05	0.04997		0.018372	2.41E+03	5:29:25 PM	-0.0438
	101	25.25	0.5	0.0011421	4.378E+05	0.04997		0.018372	2.41E+03	5:29:25 PM	-0.0433
	102	25.5	0.5	0.004859	1.029E+05	0.04997		0.018372	2.41E+03	5:29:25 PM	-0.0443
	103	25.75	0.5	-0.003109	-1.6082E+05	0.04997		0.018372	2.41E+03	5:29:25 PM	-0.0441
	104	26	0.5	0.0003871	1.2916E+06	0.04997		0.018372	2.41E+03	5:29:26 PM	-0.043
	105	26.25	0.5	0.0036484	1.3705E+05	0.04997		0.018372	2.41E+03	5:29:26 PM	-0.0429
	106	26.5	0.5	0.00045199	1.1062E+06	0.04997		0.018372	2.41E+03	5:29:26 PM	-0.0443
	107	26.75	0.5	-0.0011604	-4.3088E+05	0.04997		0.018372	2.41E+03	5:29:26 PM	-0.0441
	108	27	0.5	0.003353	1.4912E+05	0.04997		0.018372	2.41E+03	5:29:27 PM	-0.0442
	109	27.25	0.5	0.00026138	1.9129E+06	0.04997		0.018372	2.41E+03	5:29:27 PM	-0.0439
	110	27.5	0.5	1.9557E-05	2.5566E+07	0.04997		0.018372	2.41E+03	5:29:27 PM	-0.0435
	111	27.75	0.5	0.0035122	1.4236E+05	0.04997		0.018372	2.41E+03	5:29:27 PM	-0.0433
	112	28	0.5	0.00012262	4.0776E+06	0.04997		0.018372	2.41E+03	5:29:28 PM	-0.0442
	113	28.25	0.5	-0.0023524	-2.1254E+05	0.04997		0.018372	2.41E+03	5:29:28 PM	-0.0433
	114	28.5	0.5	-0.00082263	-6.078E+05	0.04997		0.018372	2.41E+03	5:29:28 PM	-0.0433
	115	28.75	0.5	0.0012777	3.9133E+05	0.04997		0.018372	2.41E+03	5:29:28 PM	-0.0423
	116	29	0.5	-0.0019722	-2.5352E+05	0.04997		0.018372	2.41E+03	5:29:29 PM	-0.0436
	117	29.25	0.5	-0.001482	-3.3738E+05	0.04997		0.018372	2.41E+03	5:29:29 PM	-0.0432
	118	29.5	0.5	0.001875	2.6667E+05	0.04997		0.018372	2.41E+03	5:29:29 PM	-0.0434
	119	29.75	0.5	-0.0034799	-1.4368E+05	0.04997		0.018372	2.41E+03	5:29:29 PM	-0.0436
	120	30	0.5	0.0022084	2.2641E+05	0.04997		0.018372	2.41E+03	5:29:30 PM	-0.0438
	121	30.25	0.5	-0.00041164	-1.2147E+06	0.04997		0.018372	2.41E+03	5:29:30 PM	-0.0443
	122	30.5	0.5	-0.00096235	-5.1956E+05	0.04997		0.018372	2.41E+03	5:29:30 PM	-0.0439
	123	30.75	0.5	0.0010387	4.8137E+05	0.04997		0.018372	2.41E+03	5:29:30 PM	-0.0431
	124	31	0.5	0.00188	2.6596E+05	0.04997		0.018372	2.41E+03	5:29:31 PM	-0.0432
	125	31.25	0.5	-0.00060533	-8.2599E+05	0.04997		0.018372	2.41E+03	5:29:31 PM	-0.0429
	126	31.5	0.5	2.5145E-05	1.9885E+07	0.04997		0.018372	2.41E+03	5:29:31 PM	-0.0429
	127	31.75	0.5	9.1578E-05	5.4598E+06	0.04997		0.018372	2.41E+03	5:29:31 PM	-0.0442
	128	32	0.5	-0.002869	-1.7428E+05	0.04997		0.018372	2.41E+03	5:29:32 PM	-0.0437
	129	32.25	0.5	0.0007205	6.9396E+05	0.04997		0.018372	2.41E+03	5:29:32 PM	-0.0437
	130	32.5	0.5	-0.0017083	-2.9269E+05	0.04997		0.018372	2.41E+03	5:29:32 PM	-0.0432
	131	32.75	0.5	-0.0014587	-3.4277E+05	0.04997		0.018372	2.41E+03	5:29:32 PM	-0.0428
	132	33	0.5	0.00044733	1.1177E+06	0.04997		0.018372	2.41E+03	5:29:33 PM	-0.0437
	133	33.25	0.5	-0.00054202	-9.2247E+05	0.04997		0.018372	2.41E+03	5:29:33 PM	-0.0441
	134	33.5	0.5	0.00059758	8.3671E+05	0.04997		0.018372	2.41E+03	5:29:33 PM	-0.0435
	135	33.75	0.5	-0.00062085	-8.0535E+05	0.04997		0.018372	2.41E+03	5:29:33 PM	-0.0426
	136	34	0.5	0.003344	1.4952E+05	0.04997		0.018372	2.41E+03	5:29:34 PM	-0.0429
	137	34.25	0.5	0.0011784	4.2431E+05	0.04997		0.018372	2.41E+03	5:29:34 PM	-0.042
	138	34.5	0.5	-0.0018886	-2.6474E+05	0.04997		0.018372	2.41E+03	5:29:34 PM	-0.0428
	139	34.75	0.5	-0.0014202	-3.5205E+05	0.04997		0.018372	2.41E+03	5:29:34 PM	-0.0436
	140	35	0.5	0.00026077	1.9174E+06	0.04997		0.018372	2.41E+03	5:29:35 PM	-0.0441
	141	35.25	0.5	0.0011027	4.5345E+05	0.04997		0.018372	2.41E+03	5:29:35 PM	-0.0439
	142	35.5	0.5	-0.0027321	-1.8301E+05	0.04997		0.018372	2.41E+03	5:29:35 PM	-0.0444
	143	35.75	0.5	-0.0011666	-4.2859E+05	0.04997		0.018372	2.41E+03	5:29:35 PM	-0.0443
	144	36	0.5	0.0027482	1.8193E+05	0.04997		0.018372	2.41E+03	5:29:36 PM	-0.0438
	145	36.25	0.5	-0.0022441	-2.228E+05	0.04997		0.018372	2.41E+03	5:29:36 PM	-0.0444
	146	36.5	0.5	-0.0042368	-1.1801E+05	0.04997		0.018372	2.41E+03	5:29:36 PM	-0.044
	147	36.75	0.5	0.0026821	1.8642E+05	0.04997		0.018372	2.41E+03	5:29:36 PM	-0.0438
	148	37	0.5	-0.0012846	-3.8923E+05	0.04997		0.018372	2.41E+03	5:29:37 PM	-0.044
	149	37.25	0.5	-0.0042719	-1.1704E+05	0.04997		0.018372	2.41E+03	5:29:37 PM	-0.0442
	150	37.5	0.5	0.001482	3.3738E+05	0.04997		0.018372	2.41E+03	5:29:37 PM	-0.0435
	151	37.75	0.5	-0.00042715	-1.1706E+06	0.04997		0.018372	2.41E+03	5:29:37 PM	-0.0434
	152	38	0.5	-0.0034691	-1.4413E+05	0.04997		0.018372	2.41E+03	5:29:38 PM	-0.0446
	153	38.25	0.5	0.0020067	2.4917E+05	0.04997		0.018372	2.41E+03	5:29:38 PM	-0.043
	154	38.5	0.5	0.00066371	7.5335E+05	0.04997		0.018372	2.41E+03	5:29:38 PM	-0.0429
	155	38.75	0.5	-0.0017201	-2.9068E+05	0.04997		0.018372	2.41E+03	5:29:38 PM	-0.044
	156	39	0.5	0.00028094	1.7797E+06	0.04997		0.018372	2.41E+03	5:29:39 PM	-0.0441
	157	39.25	0.5	0.0018486	2.7047E+05	0.04997		0.018372	2.41E+03	5:29:39 PM	-0.044
	158	39.5	0.5	-0.0033716	-1.483E+05	0.04997		0.018372	2.41E+03	5:29:39 PM	-0.044
	159	39.75	0.5	0.00090429	5.5292E+05	0.04997		0.018372	2.41E+03	5:29:39 PM	-0.0433
	160	40	0.5	0.0026567	1.882E+05	0.04997		0.018372	2.41E+03	5:29:40 PM	-0.0444
	161	40.25	0.5	0.0042818	1.1677E+05	0.04997		0.018372	2.41E+03	5:29:40 PM	-0.0436
	162	40.5	0.5	0.0040375	1.2384E+05	0.04997		0.018372	2.41E+03	5:29:40 PM	-0.0437
	163	40.75	0.5	0.0039021	1.2813E+05	0.04997		0.018372	2.41E+03	5:29:40 PM	-0.0437
	164	41	0.5	0.0019554	2.557E+05	0.04997		0.018372	2.41E+03	5:29:41 PM	-0.0439
	165	41.25	0.5	-0.0011076	-4.5141E+05	0.04997		0.018372	2.41E+03	5:29:41 PM	-0.0445
	166	41.5	0.5	0.00038773	1.2896E+06	0.04997		0.018372	2.41E+03	5:29:41 PM	-0.0438
	167	41.75	0.5	0.0015742	3.1763E+05	0.04997		0.018372	2.41E+03	5:29:41 PM	-0.0436
	168	42	0.5	0.0025983	1.9243E+05	0.04997		0.018372	2.41E+03	5:29:42 PM	-0.0437
	169	42.25	0.5	0.00044143	1.1327E+06	0.04997		0.018372	2.41E+03	5:29:42 PM	-0.0434
	170	42.5	0.5	-0.00020582	-2.4294E+06	0.04997		0.018372	2.41E+03	5:29:42 PM	-0.0436
	171	42.75	0.5	0.0044444	1.125E+05	0.04997		0.018372	2.41E+03	5:29:42 PM	-0.0435
	172	43	0.5	-1.7384E-05	-2.8762E+07	0.04997		0.018372	2.41E+03	5:29:43 PM	-0.0442
	173	43.25	0.5	0.0002381	2.0999E+06	0.04997		0.018372	2.41E+03	5:29:43 PM	-0.0438
	174	43.5	0.5	0.0023785	2.1022E+05	0.04997		0.018372	2.41E+03	5:29:43 PM	-0.0436
	175	43.75	0.5	-0.0014718	-3.3973E+05	0.04997		0.018372	2.41E+03	5:29:43 PM	-0.0444
	176	44	0.5	-0.0013308	-3.7571E+05	0.04997		0.018372	2.41E+03	5:29:44 PM	-0.0436
	177	44.25	0.5	0.0021699	2.3042E+05	0.04997		0.018372	2.41E+03	5:29:44 PM	-0.0427
	178	44.5	0.5	-0.0024486	-2.042E+05	0.04997		0.018372	2.41E+03	5:29:44 PM	-0.0424
	179	44.75	0.5	-0.0035519	-1.4077E+05	0.04997		0.018372	2.41E+03	5:29:44 PM	-0.0434
	180	45	0.5	0.0028795	1.7364E+05	0.04997		0.018372	2.41E+03	5:29:45 PM	-0.043
	181	45.25	0.5	-0.00076459	-6.5394E+05	0.04997		0.018372	2.41E+03	5:29:45 PM	-0.0434
	182	45.5	0.5	-0.0033772	-1.4805E+05	0.04997		0.018372	2.41E+03	5:29:45 PM	-0.0438
	183	45.75	0.5	0.00012107	4.13E+06	0.04997		0.018372	2.41E+03	5:29:45 PM	-0.0431
	184	46	0.5	-0.0015457	-3.2348E+05	0.04997		0.018372	2.41E+03	5:29:46 PM	-0.0435
	185	46.25	0.5	-0.00020582	-2.4293E+06	0.04997		0.018372	2.41E+03	5:29:46 PM	-0.0441
	186	46.5	0.5	-0.0016819	-2.9728E+05	0.04997		0.018372	2.41E+03	5:29:46 PM	-0.0431
	187	46.75	0.5	0.0010909	4.5835E+05	0.04997		0.018372	2.41E+03	5:29:46 PM	-0.043
	188	47	0.5	-0.0011852	-4.2186E+05	0.04997		0.018372	2.41E+03	5:29:47 PM	-0.0434
[...]
	25	6.25	20	0.10093	1.9816E+05	0.02031		0.73489	1.68E+04	5:41:11 PM	0.435
	26	6.5	20	0.070473	2.838E+05	0.02031		0.73489	1.68E+04	5:41:11 PM	0.435
	27	6.75	20	0.064665	3.0929E+05	0.02031		0.73489	1.68E+04	5:41:12 PM	0.435
	28	7	20	0.084078	2.3787E+05	0.02031		0.73489	1.68E+04	5:41:12 PM	0.435
	29	7.25	20	0.044803	4.464E+05	0.02031		0.73489	1.68E+04	5:41:12 PM	0.435
	30	7.5	20	0.055823	3.5827E+05	0.02031		0.73489	1.68E+04	5:41:12 PM	0.434
	31	7.75	20	0.052345	3.8208E+05	0.02031		0.73489	1.68E+04	5:41:13 PM	0.433
	32	8	20	0.04171	4.795E+05	0.02031		0.73489	1.68E+04	5:41:13 PM	0.435
	33	8.25	20	0.050477	3.9622E+05	0.02031		0.73489	1.68E+04	5:41:13 PM	0.435
	34	8.5	20	0.038524	5.1915E+05	0.02031		0.73489	1.68E+04	5:41:13 PM	0.434
	35	8.75	20	0.029054	6.8838E+05	0.02031		0.73489	1.68E+04	5:41:14 PM	0.434
	36	9	20	0.046869	4.2672E+05	0.02031		0.73489	1.68E+04	5:41:14 PM	0.434
	37	9.25	20	0.051021	3.9199E+05	0.02031		0.73489	1.68E+04	5:41:14 PM	0.434
	38	9.5	20	0.020525	9.7443E+05	0.02031		0.73489	1.68E+04	5:41:14 PM	0.434
	39	9.75	20	0.041924	4.7705E+05	0.0203		0.73489	1.68E+04	5:41:15 PM	0.433
	40	10	20	0.03072	6.5105E+05	0.0203		0.73489	1.68E+04	5:41:15 PM	0.432
	41	10.25	20	0.019292	1.0367E+06	0.0203		0.73489	1.68E+04	5:41:15 PM	0.431
	42	10.5	20	0.027449	7.2861E+05	0.0203		0.73489	1.68E+04	5:41:15 PM	0.432
	43	10.75	20	0.024204	8.2631E+05	0.0203		0.73489	1.68E+04	5:41:16 PM	0.432
	44	11	20	0.020889	9.5745E+05	0.0203		0.73489	1.68E+04	5:41:16 PM	0.432
	45	11.25	20	0.02691	7.4323E+05	0.0203		0.73489	1.68E+04	5:41:16 PM	0.432
	46	11.5	20	0.039289	5.0905E+05	0.0203		0.73489	1.68E+04	5:41:16 PM	0.432
	47	11.75	20	0.0043014	4.6496E+06	0.0203		0.73489	1.68E+04	5:41:17 PM	0.431
	48	12	20	0.04085	4.8959E+05	0.0203		0.73489	1.68E+04	5:41:17 PM	0.432
	49	12.25	20	0.037698	5.3053E+05	0.0203		0.73489	1.68E+04	5:41:17 PM	0.431
	50	12.5	20	0.0080752	2.4767E+06	0.0203		0.73489	1.68E+04	5:41:17 PM	0.432
	51	12.75	20	0.029078	6.878E+05	0.0203		0.73489	1.68E+04	5:41:18 PM	0.431
	52	13	20	0.034606	5.7793E+05	0.0203		0.73489	1.68E+04	5:41:18 PM	0.431
	53	13.25	20	0.0043701	4.5765E+06	0.0203		0.73489	1.68E+04	5:41:18 PM	0.431
	54	13.5	20	0.028096	7.1184E+05	0.0203		0.73489	1.68E+04	5:41:18 PM	0.431
	55	13.75	20	0.039055	5.121E+05	0.0203		0.73489	1.68E+04	5:41:19 PM	0.431
	56	14	20	-0.002833	-7.0596E+06	0.0203		0.73489	1.68E+04	5:41:19 PM	0.43
	57	14.25	20	0.025208	7.934E+05	0.0203		0.73489	1.68E+04	5:41:19 PM	0.43
	58	14.5	20	0.035724	5.5985E+05	0.0203		0.73489	1.68E+04	5:41:19 PM	0.429
	59	14.75	20	-0.006358	-3.1457E+06	0.0203		0.73489	1.68E+04	5:41:20 PM	0.43
	60	15	20	0.028067	7.1259E+05	0.0203		0.73489	1.68E+04	5:41:20 PM	0.43
	61	15.25	20	0.022741	8.7947E+05	0.0203		0.73489	1.68E+04	5:41:20 PM	0.431
	62	15.5	20	0.0041026	4.8749E+06	0.0203		0.73489	1.68E+04	5:41:20 PM	0.431
	63	15.75	20	0.01268	1.5773E+06	0.0203		0.73489	1.68E+04	5:41:21 PM	0.43
	64	16	20	0.032897	6.0797E+05	0.0203		0.73489	1.68E+04	5:41:21 PM	0.429
	65	16.25	20	-0.0036018	-5.5528E+06	0.0203		0.73489	1.68E+04	5:41:21 PM	0.429
	66	16.5	20	0.029888	6.6916E+05	0.0203		0.73489	1.68E+04	5:41:21 PM	0.43
	67	16.75	20	0.015993	1.2506E+06	0.0203		0.73489	1.68E+04	5:41:22 PM	0.43
	68	17	20	-0.0020156	-9.9224E+06	0.0203		0.73489	1.68E+04	5:41:22 PM	0.429
	69	17.25	20	0.014618	1.3682E+06	0.0203		0.73489	1.68E+04	5:41:22 PM	0.429
	70	17.5	20	0.010128	1.9747E+06	0.0203		0.73489	1.68E+04	5:41:22 PM	0.43
	71	17.75	20	0.011527	1.7351E+06	0.0203		0.73489	1.68E+04	5:41:23 PM	0.43
	72	18	20	0.016783	1.1917E+06	0.0203		0.73489	1.68E+04	5:41:23 PM	0.43
	73	18.25	20	0.026636	7.5087E+05	0.0203		0.73489	1.68E+04	5:41:23 PM	0.429
	74	18.5	20	-0.0034061	-5.8718E+06	0.0203		0.73489	1.68E+04	5:41:23 PM	0.43
	75	18.75	20	0.032211	6.209E+05	0.0203		0.73489	1.68E+04	5:41:24 PM	0.43
	76	19	20	0.011376	1.758E+06	0.0203		0.73489	1.68E+04	5:41:24 PM	0.429
	77	19.25	20	-0.0090798	-2.2027E+06	0.0203		0.73489	1.68E+04	5:41:24 PM	0.429
	78	19.5	20	0.029517	6.7757E+05	0.0203		0.73489	1.68E+04	5:41:24 PM	0.429
	79	19.75	20	0.020257	9.8731E+05	0.0203		0.73489	1.68E+04	5:41:25 PM	0.429
	80	20	20	-0.028297	-7.0679E+05	0.0203		0.73489	1.68E+04	5:41:25 PM	0.429
	81	20.25	20	0.020738	9.6443E+05	0.0203		0.73489	1.68E+04	5:41:25 PM	0.429
	82	20.5	20	0.024353	8.2125E+05	0.0203		0.73489	1.68E+04	5:41:25 PM	0.429
	83	20.75	20	-0.011571	-1.7285E+06	0.0203		0.73489	1.68E+04	5:41:26 PM	0.429
	84	21	20	0.032933	6.073E+05	0.0203		0.73489	1.68E+04	5:41:26 PM	0.428
	85	21.25	20	0.021294	9.3925E+05	0.0203		0.73489	1.68E+04	5:41:26 PM	0.429
	86	21.5	20	-0.018911	-1.0576E+06	0.0203		0.73489	1.68E+04	5:41:26 PM	0.428
	87	21.75	20	0.019817	1.0092E+06	0.0203		0.73489	1.68E+04	5:41:27 PM	0.428
	88	22	20	0.018892	1.0586E+06	0.0203		0.73489	1.68E+04	5:41:27 PM	0.428
	89	22.25	20	-0.0017421	-1.148E+07	0.0203		0.73489	1.68E+04	5:41:27 PM	0.428
	90	22.5	20	0.010638	1.88E+06	0.0203		0.73489	1.68E+04	5:41:27 PM	0.427
	91	22.75	20	0.018198	1.099E+06	0.0203		0.73489	1.68E+04	5:41:28 PM	0.428
	92	23	20	-0.010902	-1.8345E+06	0.0203		0.73489	1.68E+04	5:41:28 PM	0.428
	93	23.25	20	0.0027707	7.2184E+06	0.0203		0.73489	1.68E+04	5:41:28 PM	0.427
	94	23.5	20	0.0060348	3.3141E+06	0.0203		0.73489	1.68E+04	5:41:28 PM	0.427
	95	23.75	20	-0.0066642	-3.0011E+06	0.0203		0.73489	1.68E+04	5:41:29 PM	0.428
	96	24	20	0.019568	1.0221E+06	0.0203		0.73489	1.68E+04	5:41:29 PM	0.427
	97	24.25	20	-0.0070661	-2.8304E+06	0.0203		0.73489	1.68E+04	5:41:29 PM	0.428
	98	24.5	20	0.013831	1.446E+06	0.0203		0.73489	1.68E+04	5:41:29 PM	0.429
	99	24.75	20	0.021548	9.2815E+05	0.0203		0.73489	1.68E+04	5:41:30 PM	0.428
	100	25	20	0.0135	1.4815E+06	0.0203		0.73489	1.68E+04	5:41:30 PM	0.428
	101	25.25	20	-0.0050825	-3.9351E+06	0.0203		0.73489	1.68E+04	5:41:30 PM	0.429
	102	25.5	20	0.031055	6.4402E+05	0.0203		0.73489	1.68E+04	5:41:30 PM	0.428
	103	25.75	20	-0.0017742	-1.1273E+07	0.0203		0.73489	1.68E+04	5:41:31 PM	0.428
	104	26	20	-0.010664	-1.8755E+06	0.0203		0.73489	1.68E+04	5:41:31 PM	0.427
	105	26.25	20	0.026248	7.6195E+05	0.0203		0.73489	1.68E+04	5:41:31 PM	0.427
	106	26.5	20	0.0048749	4.1026E+06	0.0203		0.73489	1.68E+04	5:41:31 PM	0.427
	107	26.75	20	-0.0091768	-2.1794E+06	0.0203		0.73489	1.68E+04	5:41:32 PM	0.427
	108	27	20	0.020011	9.9943E+05	0.0203		0.73489	1.68E+04	5:41:32 PM	0.426
	109	27.25	20	0.0016795	1.1908E+07	0.0203		0.73489	1.68E+04	5:41:32 PM	0.427
	110	27.5	20	-0.0076016	-2.631E+06	0.0203		0.73489	1.68E+04	5:41:32 PM	0.426
	111	27.75	20	0.029728	6.7277E+05	0.0203		0.73489	1.68E+04	5:41:33 PM	0.426
	112	28	20	0.016634	1.2024E+06	0.0203		0.73489	1.68E+04	5:41:33 PM	0.426
	113	28.25	20	-0.027888	-7.1716E+05	0.0203		0.73489	1.68E+04	5:41:33 PM	0.426
	114	28.5	20	0.037762	5.2964E+05	0.0203		0.73489	1.68E+04	5:41:33 PM	0.426
	115	28.75	20	0.012795	1.5631E+06	0.0203		0.73489	1.68E+04	5:41:34 PM	0.426
	116	29	20	-0.015264	-1.3102E+06	0.0203		0.73489	1.68E+04	5:41:34 PM	0.425
	117	29.25	20	0.027357	7.3108E+05	0.0203		0.73489	1.68E+04	5:41:34 PM	0.425
	118	29.5	20	0.0051571	3.8781E+06	0.0203		0.73489	1.68E+04	5:41:34 PM	0.425
	119	29.75	20	-0.0069645	-2.8717E+06	0.0203		0.73489	1.68E+04	5:41:35 PM	0.426
	120	30	20	0.0084809	2.3582E+06	0.0203		0.73489	1.68E+04	5:41:35 PM	0.425
	121	30.25	20	0.010009	1.9983E+06	0.0203		0.73489	1.68E+04	5:41:35 PM	0.426
	122	30.5	20	-0.022214	-9.0034E+05	0.0203		0.73489	1.68E+04	5:41:35 PM	0.424
	123	30.75	20	0.031312	6.3873E+05	0.0203		0.73489	1.68E+04	5:41:36 PM	0.425
	124	31	20	0.0041936	4.7692E+06	0.0203		0.73489	1.68E+04	5:41:36 PM	0.425
	125	31.25	20	0.0032851	6.0882E+06	0.0203		0.73489	1.68E+04	5:41:36 PM	0.425
	126	31.5	20	0.025801	7.7517E+05	0.0203		0.73489	1.68E+04	5:41:36 PM	0.425
	127	31.75	20	0.011113	1.7997E+06	0.0203		0.73489	1.68E+04	5:41:37 PM	0.425
	128	32	20	-0.0041615	-4.806E+06	0.0203		0.73489	1.68E+04	5:41:37 PM	0.425
	129	32.25	20	0.0080761	2.4764E+06	0.0203		0.73489	1.68E+04	5:41:37 PM	0.425
	130	32.5	20	-0.005149	-3.8843E+06	0.0203		0.73489	1.68E+04	5:41:37 PM	0.425
	131	32.75	20	-0.014909	-1.3415E+06	0.0203		0.73489	1.68E+04	5:41:38 PM	0.426
	132	33	20	0.022618	8.8426E+05	0.0203		0.73489	1.68E+04	5:41:38 PM	0.425
	133	33.25	20	-0.015897	-1.2581E+06	0.0203		0.73489	1.68E+04	5:41:38 PM	0.425
	134	33.5	20	0.0016345	1.2236E+07	0.0203		0.73489	1.68E+04	5:41:38 PM	0.426
	135	33.75	20	0.015254	1.3111E+06	0.0203		0.73489	1.68E+04	5:41:39 PM	0.425
	136	34	20	0.00012456	1.6057E+08	0.0203		0.73489	1.68E+04	5:41:39 PM	0.425
	137	34.25	20	-0.0020708	-9.6579E+06	0.0203		0.73489	1.68E+04	5:41:39 PM	0.426
	138	34.5	20	0.02675	7.4767E+05	0.0203		0.73489	1.68E+04	5:41:39 PM	0.425
	139	34.75	20	6.8776E-05	2.908E+08	0.0203		0.73489	1.68E+04	5:41:40 PM	0.425
	140	35	20	-0.010004	-1.9992E+06	0.0203		0.73489	1.68E+04	5:41:40 PM	0.424
	141	35.25	20	0.026938	7.4244E+05	0.0203		0.73489	1.68E+04	5:41:40 PM	0.425
	142	35.5	20	-0.0095328	-2.098E+06	0.0203		0.73489	1.68E+04	5:41:40 PM	0.424
	143	35.75	20	-0.0087125	-2.2955E+06	0.0203		0.73489	1.68E+04	5:41:41 PM	0.424
	144	36	20	0.022231	8.9962E+05	0.0203		0.73489	1.68E+04	5:41:41 PM	0.425
	145	36.25	20	-0.009209	-2.1718E+06	0.0203		0.73489	1.68E+04	5:41:41 PM	0.424
	146	36.5	20	-0.015573	-1.2843E+06	0.0203		0.73489	1.68E+04	5:41:41 PM	0.425
	147	36.75	20	0.016626	1.2029E+06	0.0203		0.73489	1.68E+04	5:41:42 PM	0.425
	148	37	20	0.010265	1.9483E+06	0.0203		0.73489	1.68E+04	5:41:42 PM	0.425
	149	37.25	20	-0.023679	-8.4462E+05	0.0203		0.73489	1.68E+04	5:41:42 PM	0.425
	150	37.5	20	0.032734	6.1098E+05	0.0203		0.73489	1.68E+04	5:41:42 PM	0.425
	151	37.75	20	0.0020227	9.8876E+06	0.0203		0.73489	1.68E+04	5:41:43 PM	0.425
	152	38	20	-0.0045829	-4.3641E+06	0.0203		0.73489	1.68E+04	5:41:43 PM	0.425
	153	38.25	20	0.015345	1.3034E+06	0.0203		0.73489	1.68E+04	5:41:43 PM	0.426
	154	38.5	20	0.0013067	1.5306E+07	0.0203		0.73489	1.68E+04	5:41:43 PM	0.425
	155	38.75	20	-0.010536	-1.8982E+06	0.0203		0.73489	1.68E+04	5:41:44 PM	0.425
	156	39	20	0.0015834	1.2631E+07	0.0203		0.73489	1.68E+04	5:41:44 PM	0.424
	157	39.25	20	0.010411	1.921E+06	0.0203		0.73489	1.68E+04	5:41:44 PM	0.425
	158	39.5	20	-0.0039475	-5.0665E+06	0.0203		0.73489	1.68E+04	5:41:44 PM	0.425
	159	39.75	20	0.010453	1.9134E+06	0.0203		0.73489	1.68E+04	5:41:45 PM	0.425
	160	40	20	-0.0088361	-2.2634E+06	0.0203		0.73489	1.68E+04	5:41:45 PM	0.424
	161	40.25	20	-0.002958	-6.7612E+06	0.0203		0.73489	1.68E+04	5:41:45 PM	0.425
	162	40.5	20	0.013756	1.4539E+06	0.0203		0.73489	1.68E+04	5:41:45 PM	0.425
	163	40.75	20	-0.0050589	-3.9534E+06	0.0203		0.73489	1.68E+04	5:41:46 PM	0.424
	164	41	20	0.0095176	2.1014E+06	0.0203		0.73489	1.68E+04	5:41:46 PM	0.424
	165	41.25	20	0.022853	8.7516E+05	0.0203		0.73489	1.68E+04	5:41:46 PM	0.424
	166	41.5	20	-0.0019923	-1.0039E+07	0.0203		0.73489	1.68E+04	5:41:46 PM	0.424
	167	41.75	20	-0.002437	-8.2067E+06	0.0203		0.73489	1.68E+04	5:41:47 PM	0.424
	168	42	20	0.0236	8.4745E+05	0.0203		0.73489	1.68E+04	5:41:47 PM	0.423
	169	42.25	20	-0.013335	-1.4998E+06	0.0203		0.73489	1.68E+04	5:41:47 PM	0.423
	170	42.5	20	-0.011514	-1.737E+06	0.0203		0.73489	1.68E+04	5:41:47 PM	0.423
	171	42.75	20	0.032069	6.2365E+05	0.0203		0.73489	1.68E+04	5:41:48 PM	0.423
	172	43	20	-0.025515	-7.8384E+05	0.0203		0.73489	1.68E+04	5:41:48 PM	0.423
	173	43.25	20	-0.011607	-1.723E+06	0.0203		0.73489	1.68E+04	5:41:48 PM	0.422
	174	43.5	20	0.034768	5.7524E+05	0.0203		0.73489	1.68E+04	5:41:48 PM	0.423
	175	43.75	20	-0.0022292	-8.9717E+06	0.0203		0.73489	1.68E+04	5:41:49 PM	0.422
	176	44	20	-0.018646	-1.0726E+06	0.0203		0.73489	1.68E+04	5:41:49 PM	0.423
	177	44.25	20	0.038015	5.2611E+05	0.0203		0.73489	1.68E+04	5:41:49 PM	0.424
	178	44.5	20	-0.0044102	-4.535E+06	0.0203		0.73489	1.68E+04	5:41:49 PM	0.424
	179	44.75	20	-0.016501	-1.212E+06	0.0203		0.73489	1.68E+04	5:41:50 PM	0.425
	180	45	20	0.017396	1.1497E+06	0.0203		0.73489	1.68E+04	5:41:50 PM	0.425
	181	45.25	20	-0.0084455	-2.3681E+06	0.0203		0.73489	1.68E+04	5:41:50 PM	0.425
	182	45.5	20	0.0011562	1.7299E+07	0.0203		0.73489	1.68E+04	5:41:50 PM	0.425
	183	45.75	20	0.0070502	2.8368E+06	0.0203		0.73489	1.68E+04	5:41:51 PM	0.426
	184	46	20	-0.016155	-1.238E+06	0.0203		0.73489	1.68E+04	5:41:51 PM	0.424
	185	46.25	20	0.0053386	3.7463E+06	0.0203		0.73489	1.68E+04	5:41:51 PM	0.424

Test:	std d=0.02mm 50pa

Result:	steady stress 1

Interval and data points:	1	113
Interval data:	Point No.	Time	Shear Stress	Shear Rate	Viscosity	Gap	Complex Viscosity	Torque	Shear Strain	Time of Day	Normal Force

		[s]	[Pa]	[1/s]	[mPa·s]	[mm]	[mPa·s]	[mN·m]	[%]	[]	[N]
	1	0.25	50	971.77	51.452	0.02035		1.8372	8.76E+03	5:42:41 PM	0.486
	2	0.5	50	2066.7	24.193	0.02036		1.8372	5.08E+04	5:42:41 PM	0.512
	3	0.75	50	3255.7	15.357	0.02053		1.8372	1.17E+05	5:42:42 PM	0.754
	4	1	50	4179.6	11.963	0.0205		1.8372	2.11E+05	5:42:42 PM	0.699
	5	1.25	50	4699.7	10.639	0.02041		1.8372	3.23E+05	5:42:42 PM	0.577
	6	1.5	50	5233.1	9.5545	0.0204		1.8372	4.48E+05	5:42:42 PM	0.575
	7	1.75	50	5408.4	9.2448	0.02041		1.8372	5.82E+05	5:42:43 PM	0.576
	8	2	50	5498.9	9.0927	0.02031		1.8372	7.22E+05	5:42:43 PM	0.437
	9	2.25	50	5346.3	9.3523	0.02022		1.8372	8.6E+05	5:42:43 PM	0.306
	10	2.5	50	5578.5	8.963	0.02027		1.8372	9.95E+05	5:42:43 PM	0.387
	11	2.75	50	5605	8.9205	0.02045		1.8372	1.12E+06	5:42:44 PM	0.63
	12	3	50	5903.7	8.4693	0.0203		1.8372	1.28E+06	5:42:44 PM	0.424
	13	3.25	50	5905.2	8.4671	0.02018		1.8372	1.43E+06	5:42:44 PM	0.253
	14	3.5	50	5813.8	8.6002	0.02035		1.8372	1.57E+06	5:42:44 PM	0.509
	15	3.75	50	5861.3	8.5306	0.02025		1.8372	1.72E+06	5:42:45 PM	0.347
	16	4	50	5704.7	8.7648	0.02021		1.8372	1.87E+06	5:42:45 PM	0.296
	17	4.25	50	5806.3	8.6114	0.02018		1.8372	2.02E+06	5:42:45 PM	0.261
	18	4.5	50	5496	9.0975	0.02032		1.8372	2.14E+06	5:42:45 PM	0.454
	19	4.75	50	5716.8	8.7462	0.0202		1.8372	2.3E+06	5:42:46 PM	0.28
	20	5	50	5528.2	9.0445	0.02014		1.8372	2.44E+06	5:42:46 PM	0.194
	21	5.25	50	5639	8.8668	0.02026		1.8372	2.57E+06	5:42:46 PM	0.375
	22	5.5	50	5477.7	9.1278	0.02027		1.8372	2.71E+06	5:42:46 PM	0.374
	23	5.75	50	5608.5	8.915	0.02018		1.8372	2.86E+06	5:42:47 PM	0.264
	24	6	50	5541.6	9.0226	0.02011		1.8372	3.01E+06	5:42:47 PM	0.16
	25	6.25	50	5460.3	9.1569	0.02032		1.8372	3.11E+06	5:42:47 PM	0.465
	26	6.5	50	5535.2	9.0331	0.02023		1.8372	3.26E+06	5:42:47 PM	0.317
	27	6.75	50	5483.9	9.1176	0.02019		1.8372	3.41E+06	5:42:48 PM	0.273
	28	7	50	5590.1	8.9445	0.02013		1.8372	3.56E+06	5:42:48 PM	0.187
	29	7.25	50	5361.9	9.325	0.02034		1.8372	3.66E+06	5:42:48 PM	0.482
	30	7.5	50	5589.9	8.9448	0.0202		1.8372	3.82E+06	5:42:48 PM	0.285
	31	7.75	50	5416.5	9.2311	0.02018		1.8372	3.96E+06	5:42:49 PM	0.245
	32	8	50	5608.9	8.9144	0.02018		1.8372	4.1E+06	5:42:49 PM	0.261
	33	8.25	50	5322.5	9.394	0.02031		1.8372	4.21E+06	5:42:49 PM	0.439
	34	8.5	50	5584.9	8.9527	0.02019		1.8372	4.37E+06	5:42:49 PM	0.269
	35	8.75	50	5435.9	9.1981	0.02014		1.8372	4.52E+06	5:42:50 PM	0.192
	36	9	50	5577.6	8.9645	0.02025		1.8372	4.63E+06	5:42:50 PM	0.358
	37	9.25	50	5421.5	9.2225	0.02027		1.8372	4.76E+06	5:42:50 PM	0.38
	38	9.5	50	5582.6	8.9564	0.02018		1.8372	4.92E+06	5:42:50 PM	0.256
	39	9.75	50	5515.6	9.0653	0.02011		1.8372	5.08E+06	5:42:51 PM	0.16
	40	10	50	5493.8	9.1011	0.02031		1.8372	5.17E+06	5:42:51 PM	0.444
	41	10.25	50	5504.5	9.0834	0.02024		1.8372	5.32E+06	5:42:51 PM	0.328
	42	10.5	50	5501.7	9.0881	0.02019		1.8372	5.47E+06	5:42:51 PM	0.271
	43	10.75	50	5557.2	8.9974	0.02012		1.8372	5.63E+06	5:42:52 PM	0.17
	44	11	50	5361.7	9.3255	0.02033		1.8372	5.71E+06	5:42:52 PM	0.478
	45	11.25	50	5544.8	9.0175	0.02021		1.8372	5.88E+06	5:42:52 PM	0.29
	46	11.5	50	5402.8	9.2544	0.0202		1.8372	6.02E+06	5:42:52 PM	0.271
	47	11.75	50	5570.6	8.9757	0.02015		1.8372	6.17E+06	5:42:53 PM	0.227
	48	12	50	5246.6	9.5301	0.02033		1.8372	6.25E+06	5:42:53 PM	0.459
	49	12.25	50	5528.3	9.0444	0.02019		1.8372	6.43E+06	5:42:53 PM	0.271
	50	12.5	50	5353.7	9.3393	0.02015		1.8372	6.58E+06	5:42:53 PM	0.214
	51	12.75	50	5543.9	9.0189	0.0202		1.8372	6.7E+06	5:42:54 PM	0.298
	52	13	50	5316	9.4055	0.0203		1.8372	6.8E+06	5:42:54 PM	0.414
	53	13.25	50	5541.7	9.0225	0.02018		1.8372	6.98E+06	5:42:54 PM	0.26
	54	13.5	50	5377.9	9.2974	0.02013		1.8372	7.13E+06	5:42:54 PM	0.175
	55	13.75	50	5496.8	9.0961	0.02026		1.8372	7.22E+06	5:42:55 PM	0.379
	56	14	50	5370.8	9.3096	0.02026		1.8372	7.35E+06	5:42:55 PM	0.367
	57	14.25	50	5519.4	9.059	0.02018		1.8372	7.52E+06	5:42:55 PM	0.258
	58	14.5	50	5440.8	9.1898	0.02012		1.8372	7.68E+06	5:42:55 PM	0.163
	59	14.75	50	5415.3	9.2331	0.02031		1.8372	7.75E+06	5:42:56 PM	0.451
	60	15	50	5451.1	9.1725	0.02023		1.8372	7.91E+06	5:42:56 PM	0.326
	61	15.25	50	5432.9	9.2032	0.02019		1.8372	8.06E+06	5:42:56 PM	0.273
	62	15.5	50	5496.8	9.0961	0.02012		1.8372	8.23E+06	5:42:56 PM	0.172
	63	15.75	50	5325.8	9.3883	0.02034		1.8372	8.27E+06	5:42:57 PM	0.477
	64	16	50	5499.2	9.0922	0.02021		1.8372	8.46E+06	5:42:57 PM	0.294
	65	16.25	50	5383.4	9.2879	0.0202		1.8372	8.6E+06	5:42:57 PM	0.279
	66	16.5	50	5541.5	9.0228	0.02014		1.8372	8.76E+06	5:42:57 PM	0.213
	67	16.75	50	5280	9.4697	0.02034		1.8372	8.82E+06	5:42:58 PM	0.472
	68	17	50	5538.7	9.0274	0.0202		1.8372	9.01E+06	5:42:58 PM	0.273
	69	17.25	50	5361.7	9.3253	0.02016		1.8372	9.17E+06	5:42:58 PM	0.224
	70	17.5	50	5558.5	8.9953	0.02019		1.8372	9.29E+06	5:42:58 PM	0.285
	71	17.75	50	5258.6	9.5083	0.0203		1.8372	9.37E+06	5:42:59 PM	0.429
	72	18	50	5519.2	9.0592	0.02018		1.8372	9.56E+06	5:42:59 PM	0.262
	73	18.25	50	5362.1	9.3246	0.02014		1.8372	9.72E+06	5:42:59 PM	0.187
	74	18.5	50	5472.4	9.1367	0.02025		1.8372	9.8E+06	5:42:59 PM	0.363
	75	18.75	50	5265.2	9.4963	0.02027		1.8372	9.92E+06	5:43:00 PM	0.384
	76	19	50	5458.5	9.1601	0.02017		1.8372	1.01E+07	5:43:00 PM	0.249
	77	19.25	50	5348	9.3492	0.02012		1.8372	1.03E+07	5:43:00 PM	0.161
	78	19.5	50	5397.3	9.2638	0.02028		1.8372	1.03E+07	5:43:00 PM	0.411
	79	19.75	50	5330	9.3809	0.02025		1.8372	1.05E+07	5:43:01 PM	0.354
	80	20	50	5446.7	9.1799	0.02018		1.8372	1.06E+07	5:43:01 PM	0.264
	81	20.25	50	5424.1	9.2181	0.02011		1.8372	1.08E+07	5:43:01 PM	0.158
	82	20.5	50	5341.6	9.3605	0.02032		1.8372	1.08E+07	5:43:01 PM	0.467
	83	20.75	50	5414.7	9.234	0.02023		1.8372	1.1E+07	5:43:02 PM	0.32
	84	21	50	5401.4	9.2568	0.02019		1.8372	1.12E+07	5:43:02 PM	0.269
	85	21.25	50	5478.8	9.1261	0.02012		1.8372	1.14E+07	5:43:02 PM	0.173
	86	21.5	50	5267.7	9.4917	0.02034		1.8372	1.14E+07	5:43:02 PM	0.48
	87	21.75	50	5453.9	9.1677	0.02021		1.8372	1.16E+07	5:43:03 PM	0.293
	88	22	50	5344.3	9.3557	0.0202		1.8372	1.17E+07	5:43:03 PM	0.278
	89	22.25	50	5525.6	9.0489	0.02015		1.8372	1.19E+07	5:43:03 PM	0.215
	90	22.5	50	5220.6	9.5774	0.02034		1.8372	1.19E+07	5:43:03 PM	0.478
	91	22.75	50	5499.1	9.0924	0.0202		1.8372	1.21E+07	5:43:04 PM	0.274
	92	23	50	5310	9.4163	0.02017		1.8372	1.23E+07	5:43:04 PM	0.235
	93	23.25	50	5512.5	9.0703	0.02018		1.8372	1.24E+07	5:43:04 PM	0.269
	94	23.5	50	5227.6	9.5647	0.02031		1.8372	1.25E+07	5:43:04 PM	0.437
	95	23.75	50	5499.1	9.0923	0.02019		1.8372	1.27E+07	5:43:05 PM	0.265
	96	24	50	5303	9.4287	0.02015		1.8372	1.28E+07	5:43:05 PM	0.204
	97	24.25	50	5488	9.1108	0.02023		1.8372	1.29E+07	5:43:05 PM	0.34
	98	24.5	50	5280.3	9.4691	0.02029		1.8372	1.3E+07	5:43:05 PM	0.4
	99	24.75	50	5499.5	9.0917	0.02018		1.8372	1.32E+07	5:43:06 PM	0.247
	100	25	50	5337	9.3686	0.02012		1.8372	1.34E+07	5:43:06 PM	0.171
	101	25.25	50	5435.5	9.1988	0.02027		1.8372	1.34E+07	5:43:06 PM	0.395
	102	25.5	50	5319.3	9.3998	0.02026		1.8372	1.36E+07	5:43:06 PM	0.36
	103	25.75	50	5469.8	9.1412	0.02018		1.8372	1.38E+07	5:43:07 PM	0.257
	104	26	50	5400.5	9.2583	0.02012		1.8372	1.39E+07	5:43:07 PM	0.163
	105	26.25	50	5364.2	9.321	0.02031		1.8372	1.39E+07	5:43:07 PM	0.454
	106	26.5	50	5376	9.3007	0.02024		1.8372	1.41E+07	5:43:07 PM	0.329
	107	26.75	50	5418.5	9.2276	0.02019		1.8372	1.43E+07	5:43:08 PM	0.267
	108	27	50	5457.4	9.1619	0.02012		1.8372	1.45E+07	5:43:08 PM	0.169
	109	27.25	50	5268.7	9.4899	0.02034		1.8372	1.44E+07	5:43:08 PM	0.479
	110	27.5	50	5430.5	9.2073	0.02021		1.8372	1.47E+07	5:43:08 PM	0.301
	111	27.75	50	5366	9.3179	0.02019		1.8372	1.48E+07	5:43:09 PM	0.278
	112	28	50	5499.1	9.0924	0.02014		1.8372	1.5E+07	5:43:09 PM	0.203
	113	28.25	50	5231.4	9.5577	0.02034		1.8372	1.5E+07	5:43:09 PM	0.485